<?xml version="1.0" encoding="UTF-8"?>
<!-- Generated by org.testng.reporters.JUnitReportReporter -->
<testsuite hostname="linh-truong-pc" failures="1" tests="2" name="com.nopcommerce.account.Level_18_ExtentReport2" time="4.422" errors="1" timestamp="2023-09-20T16:42:11 EEST" skipped="0">
  <testcase classname="com.nopcommerce.account.Level_18_ExtentReport2" name="User_01_Register_Validate" time="2.236">
    <error message="Multiple failures (2):
Failure 1 of 2
java.lang.AssertionError: expected [false] but found [true]
	at org.testng.Assert.fail(Assert.java:111)
	at org.testng.Assert.failNotEquals(Assert.java:1578)
	at org.testng.Assert.assertFalse(Assert.java:79)
	at org.testng.Assert.assertFalse(Assert.java:89)
	at commons.BaseTest.verifyFalse(BaseTest.java:137)
	at com.nopcommerce.account.Level_18_ExtentReport2.User_01_Register_Validate(Level_18_ExtentReport2.java:43)
	at java.base/jdk.internal.reflect.NativeMethodAccessorImpl.invoke0(Native Method)
	at java.base/jdk.internal.reflect.NativeMethodAccessorImpl.invoke(NativeMethodAccessorImpl.java:62)
	at java.base/jdk.internal.reflect.DelegatingMethodAccessorImpl.invoke(DelegatingMethodAccessorImpl.java:43)
	at java.base/java.lang.reflect.Method.invoke(Method.java:566)
	at org.testng.internal.invokers.MethodInvocationHelper.invokeMethod(MethodInvocationHelper.java:139)
	at org.testng.internal.invokers.TestInvoker.invokeMethod(TestInvoker.java:664)
	at org.testng.internal.invokers.TestInvoker.invokeTestMethod(TestInvoker.java:227)
	at org.testng.internal.invokers.MethodRunner.runInSequence(MethodRunner.java:50)
	at org.testng.internal.invokers.TestInvoker$MethodInvocationAgent.invoke(TestInvoker.java:957)
	at org.testng.internal.invokers.TestInvoker.invokeTestMethods(TestInvoker.java:200)
	at org.testng.internal.invokers.TestMethodWorker.invokeTestMethods(TestMethodWorker.java:148)
	at org.testng.internal.invokers.TestMethodWorker.run(TestMethodWorker.java:128)
	at java.base/java.util.ArrayList.forEach(ArrayList.java:1541)
	at org.testng.TestRunner.privateRun(TestRunner.java:848)
	at org.testng.TestRunner.run(TestRunner.java:621)
	at org.testng.SuiteRunner.runTest(SuiteRunner.java:443)
	at org.testng.SuiteRunner.runSequentially(SuiteRunner.java:437)
	at org.testng.SuiteRunner.privateRun(SuiteRunner.java:397)
	at org.testng.SuiteRunner.run(SuiteRunner.java:336)
	at org.testng.SuiteRunnerWorker.runSuite(SuiteRunnerWorker.java:52)
	at org.testng.SuiteRunnerWorker.run(SuiteRunnerWorker.java:95)
	at org.testng.TestNG.runSuitesSequentially(TestNG.java:1280)
	at org.testng.TestNG.runSuitesLocally(TestNG.java:1200)
	at org.testng.TestNG.runSuites(TestNG.java:1114)
	at org.testng.TestNG.run(TestNG.java:1082)
	at org.testng.remote.AbstractRemoteTestNG.run(AbstractRemoteTestNG.java:115)
	at org.testng.remote.RemoteTestNG.initAndRun(RemoteTestNG.java:251)
	at org.testng.remote.RemoteTestNG.main(RemoteTestNG.java:77)

Failure 2 of 2
java.lang.AssertionError: expected [Last name is required] but found [Last name is required.]" type="java.lang.Throwable">
      <![CDATA[java.lang.Throwable: Multiple failures (2):
Failure 1 of 2
java.lang.AssertionError: expected [false] but found [true]
at org.testng.Assert.fail(Assert.java:111)
at org.testng.Assert.failNotEquals(Assert.java:1578)
at org.testng.Assert.assertFalse(Assert.java:79)
at org.testng.Assert.assertFalse(Assert.java:89)
at commons.BaseTest.verifyFalse(BaseTest.java:137)
at com.nopcommerce.account.Level_18_ExtentReport2.User_01_Register_Validate(Level_18_ExtentReport2.java:43)
at java.base/jdk.internal.reflect.NativeMethodAccessorImpl.invoke0(Native Method)
at java.base/jdk.internal.reflect.NativeMethodAccessorImpl.invoke(NativeMethodAccessorImpl.java:62)
at java.base/jdk.internal.reflect.DelegatingMethodAccessorImpl.invoke(DelegatingMethodAccessorImpl.java:43)
at java.base/java.lang.reflect.Method.invoke(Method.java:566)
at org.testng.internal.invokers.MethodInvocationHelper.invokeMethod(MethodInvocationHelper.java:139)
at org.testng.internal.invokers.TestInvoker.invokeMethod(TestInvoker.java:664)
at org.testng.internal.invokers.TestInvoker.invokeTestMethod(TestInvoker.java:227)
at org.testng.internal.invokers.MethodRunner.runInSequence(MethodRunner.java:50)
at org.testng.internal.invokers.TestInvoker$MethodInvocationAgent.invoke(TestInvoker.java:957)
at org.testng.internal.invokers.TestInvoker.invokeTestMethods(TestInvoker.java:200)
at org.testng.internal.invokers.TestMethodWorker.invokeTestMethods(TestMethodWorker.java:148)
at org.testng.internal.invokers.TestMethodWorker.run(TestMethodWorker.java:128)
at java.base/java.util.ArrayList.forEach(ArrayList.java:1541)
at org.testng.TestRunner.privateRun(TestRunner.java:848)
at org.testng.TestRunner.run(TestRunner.java:621)
at org.testng.SuiteRunner.runTest(SuiteRunner.java:443)
at org.testng.SuiteRunner.runSequentially(SuiteRunner.java:437)
at org.testng.SuiteRunner.privateRun(SuiteRunner.java:397)
at org.testng.SuiteRunner.run(SuiteRunner.java:336)
at org.testng.SuiteRunnerWorker.runSuite(SuiteRunnerWorker.java:52)
at org.testng.SuiteRunnerWorker.run(SuiteRunnerWorker.java:95)
at org.testng.TestNG.runSuitesSequentially(TestNG.java:1280)
at org.testng.TestNG.runSuitesLocally(TestNG.java:1200)
at org.testng.TestNG.runSuites(TestNG.java:1114)
at org.testng.TestNG.run(TestNG.java:1082)
at org.testng.remote.AbstractRemoteTestNG.run(AbstractRemoteTestNG.java:115)
at org.testng.remote.RemoteTestNG.initAndRun(RemoteTestNG.java:251)
at org.testng.remote.RemoteTestNG.main(RemoteTestNG.java:77)

Failure 2 of 2
java.lang.AssertionError: expected [Last name is required] but found [Last name is required.]
at org.testng.Assert.fail(Assert.java:111)
at org.testng.Assert.failNotEquals(Assert.java:1578)
at org.testng.Assert.assertEqualsImpl(Assert.java:150)
at org.testng.Assert.assertEquals(Assert.java:132)
at org.testng.Assert.assertEquals(Assert.java:644)
at commons.BaseTest.verifyEquals(BaseTest.java:151)
at com.nopcommerce.account.Level_18_ExtentReport2.User_01_Register_Validate(Level_18_ExtentReport2.java:55)
at java.base/jdk.internal.reflect.NativeMethodAccessorImpl.invoke0(Native Method)
at java.base/jdk.internal.reflect.NativeMethodAccessorImpl.invoke(NativeMethodAccessorImpl.java:62)
at java.base/jdk.internal.reflect.DelegatingMethodAccessorImpl.invoke(DelegatingMethodAccessorImpl.java:43)
at java.base/java.lang.reflect.Method.invoke(Method.java:566)
at org.testng.internal.invokers.MethodInvocationHelper.invokeMethod(MethodInvocationHelper.java:139)
at org.testng.internal.invokers.TestInvoker.invokeMethod(TestInvoker.java:664)
at org.testng.internal.invokers.TestInvoker.invokeTestMethod(TestInvoker.java:227)
at org.testng.internal.invokers.MethodRunner.runInSequence(MethodRunner.java:50)
at org.testng.internal.invokers.TestInvoker$MethodInvocationAgent.invoke(TestInvoker.java:957)
at org.testng.internal.invokers.TestInvoker.invokeTestMethods(TestInvoker.java:200)
at org.testng.internal.invokers.TestMethodWorker.invokeTestMethods(TestMethodWorker.java:148)
at org.testng.internal.invokers.TestMethodWorker.run(TestMethodWorker.java:128)
at java.base/java.util.ArrayList.forEach(ArrayList.java:1541)
at org.testng.TestRunner.privateRun(TestRunner.java:848)
at org.testng.TestRunner.run(TestRunner.java:621)
at org.testng.SuiteRunner.runTest(SuiteRunner.java:443)
at org.testng.SuiteRunner.runSequentially(SuiteRunner.java:437)
at org.testng.SuiteRunner.privateRun(SuiteRunner.java:397)
at org.testng.SuiteRunner.run(SuiteRunner.java:336)
at org.testng.SuiteRunnerWorker.runSuite(SuiteRunnerWorker.java:52)
at org.testng.SuiteRunnerWorker.run(SuiteRunnerWorker.java:95)
at org.testng.TestNG.runSuitesSequentially(TestNG.java:1280)
at org.testng.TestNG.runSuitesLocally(TestNG.java:1200)
at org.testng.TestNG.runSuites(TestNG.java:1114)
at org.testng.TestNG.run(TestNG.java:1082)
at org.testng.remote.AbstractRemoteTestNG.run(AbstractRemoteTestNG.java:115)
at org.testng.remote.RemoteTestNG.initAndRun(RemoteTestNG.java:251)
at org.testng.remote.RemoteTestNG.main(RemoteTestNG.java:77)
]]>
    </error>
    <system-out>
      <![CDATA[..............FAILED..............
..............PASSED..............
..............FAILED..............]]>
    </system-out>
  </testcase> <!-- User_01_Register_Validate -->
  <testcase classname="com.nopcommerce.account.Level_18_ExtentReport2" name="User_02_Register_Success" time="2.186">
    <failure message="expected [Your registration completed..] but found [Your registration completed]" type="java.lang.AssertionError">
      <![CDATA[java.lang.AssertionError: expected [Your registration completed..] but found [Your registration completed]
at org.testng.Assert.fail(Assert.java:111)
at org.testng.Assert.failNotEquals(Assert.java:1578)
at org.testng.Assert.assertEqualsImpl(Assert.java:150)
at org.testng.Assert.assertEquals(Assert.java:132)
at org.testng.Assert.assertEquals(Assert.java:644)
at commons.BaseTest.verifyEquals(BaseTest.java:151)
at com.nopcommerce.account.Level_18_ExtentReport2.User_02_Register_Success(Level_18_ExtentReport2.java:83)
at java.base/jdk.internal.reflect.NativeMethodAccessorImpl.invoke0(Native Method)
at java.base/jdk.internal.reflect.NativeMethodAccessorImpl.invoke(NativeMethodAccessorImpl.java:62)
at java.base/jdk.internal.reflect.DelegatingMethodAccessorImpl.invoke(DelegatingMethodAccessorImpl.java:43)
at java.base/java.lang.reflect.Method.invoke(Method.java:566)
at org.testng.internal.invokers.MethodInvocationHelper.invokeMethod(MethodInvocationHelper.java:139)
at org.testng.internal.invokers.TestInvoker.invokeMethod(TestInvoker.java:664)
at org.testng.internal.invokers.TestInvoker.invokeTestMethod(TestInvoker.java:227)
at org.testng.internal.invokers.MethodRunner.runInSequence(MethodRunner.java:50)
at org.testng.internal.invokers.TestInvoker$MethodInvocationAgent.invoke(TestInvoker.java:957)
at org.testng.internal.invokers.TestInvoker.invokeTestMethods(TestInvoker.java:200)
at org.testng.internal.invokers.TestMethodWorker.invokeTestMethods(TestMethodWorker.java:148)
at org.testng.internal.invokers.TestMethodWorker.run(TestMethodWorker.java:128)
at java.base/java.util.ArrayList.forEach(ArrayList.java:1541)
at org.testng.TestRunner.privateRun(TestRunner.java:848)
at org.testng.TestRunner.run(TestRunner.java:621)
at org.testng.SuiteRunner.runTest(SuiteRunner.java:443)
at org.testng.SuiteRunner.runSequentially(SuiteRunner.java:437)
at org.testng.SuiteRunner.privateRun(SuiteRunner.java:397)
at org.testng.SuiteRunner.run(SuiteRunner.java:336)
at org.testng.SuiteRunnerWorker.runSuite(SuiteRunnerWorker.java:52)
at org.testng.SuiteRunnerWorker.run(SuiteRunnerWorker.java:95)
at org.testng.TestNG.runSuitesSequentially(TestNG.java:1280)
at org.testng.TestNG.runSuitesLocally(TestNG.java:1200)
at org.testng.TestNG.runSuites(TestNG.java:1114)
at org.testng.TestNG.run(TestNG.java:1082)
at org.testng.remote.AbstractRemoteTestNG.run(AbstractRemoteTestNG.java:115)
at org.testng.remote.RemoteTestNG.initAndRun(RemoteTestNG.java:251)
at org.testng.remote.RemoteTestNG.main(RemoteTestNG.java:77)
]]>
    </failure>
    <system-out>
      <![CDATA[..............FAILED..............]]>
    </system-out>
  </testcase> <!-- User_02_Register_Success -->
  <system-out>
    <![CDATA[..............FAILED..............
..............PASSED..............
..............FAILED..............
..............FAILED..............]]>
  </system-out>
</testsuite> <!-- com.nopcommerce.account.Level_18_ExtentReport2 -->
